<?xml version="1.0" ?>
<robot name="turtlebot3" xmlns:xacro="http://ros.org/wiki/xacro">

  <xacro:property name="astra_cam_px" value="0.13"/>
  <xacro:property name="astra_cam_py" value="0.008"/>
  <xacro:property name="astra_cam_pz" value="0.06"/>
  <xacro:property name="astra_depth_rel_rgb_py" value="0.0250" />
  <xacro:property name="astra_cam_rel_rgb_py"   value="-0.0125" />
  <xacro:property name="astra_dae_display_scale"   value="0.5" />
  <xacro:property name="M_PI" value="3.1415926535897931" />

  <material name="black">
    <color rgba="0.0 0.0 0.0 1.0"/>
  </material>
  <material name="orange">
    <color rgba="1.0 0.4 0.0 1.0"/>
  </material>

  <link name="base_footprint"/>

  <joint name="base_joint" type="fixed">
    <origin xyz="0 0 0.033" rpy="0 0 0"/>
    <parent link="base_footprint"/>
    <child link="base_link" />
  </joint>

  <link name="base_link">
    <visual>
      <origin xyz="0.06 0 0.007" rpy="0 0 0"/>
      <geometry>
        <box size="0.18 0.12 0.04"/>
      </geometry>
    </visual>
    <collision>
      <origin xyz="0.06 0 0.007" rpy="0 0 0"/>
      <geometry>
        <box size="0.18 0.12 0.08"/>
      </geometry>
    </collision>
    <inertial>
      <origin xyz="0.06 0 0.007" rpy="0 0 0"/>
      <mass value="1"/>
      <inertia ixx="0.01" ixy="0.0" ixz="0.0"
               iyy="0.01" iyz="0.0"
               izz="0.01" />
    </inertial>
  </link>

  <joint name="wheel_left_joint" type="continuous">
    <parent link="base_link"/>
    <child link="wheel_left_link"/>
    <origin xyz="0 0.075 0" rpy="-1.570796327 0 0"/>
    <axis xyz="0 0 1"/>
  </joint>

  <link name="wheel_left_link">
    <visual>
      <origin xyz="0 0 0" rpy="0 0 0"/>
      <geometry>
        <cylinder length="0.018" radius="0.033"/>
      </geometry>
      <material name="black"/>
    </visual>
    <collision>
      <origin rpy="0 0 0" xyz="0 0 0"/>
      <geometry>
        <cylinder length="0.018" radius="0.033"/>
      </geometry>
    </collision>
    <inertial>
      <origin xyz="0 0 0" />
      <mass value="0.01" />
      <inertia ixx="0.001" ixy="0.0" ixz="0.0"
               iyy="0.001" iyz="0.0"
               izz="0.001" />
    </inertial>
  </link>

  <joint name="wheel_right_joint" type="continuous">
    <parent link="base_link"/>
    <child link="wheel_right_link"/>
    <origin xyz="0 -0.075 0" rpy="-1.570796327 0 0"/>
    <axis xyz="0 0 1"/>
  </joint>

  <link name="wheel_right_link">
    <visual>
      <origin xyz="0 0 0" rpy="0 0 0"/>
      <geometry>
        <cylinder length="0.018" radius="0.033"/>
      </geometry>
      <material name="black"/>
    </visual>
    <collision>
      <origin rpy="0 0 0" xyz="0 0 0"/>
      <geometry>
        <cylinder length="0.018" radius="0.033"/>
      </geometry>
    </collision>
    <inertial>
      <origin xyz="0 0 0" />
      <mass value="0.01" />
      <inertia ixx="0.001" ixy="0.0" ixz="0.0"
               iyy="0.001" iyz="0.0"
               izz="0.001" />
    </inertial>
  </link>

  <joint name="camera_rgb_joint" type="fixed">
    <origin xyz="${astra_cam_px} ${astra_cam_py} ${astra_cam_pz}"
            rpy="0 0 0"/>
    <parent link="base_link"/>
    <child link="camera_rgb_frame" />
  </joint>
  <link name="camera_rgb_frame"/>

  <joint name="camera_rgb_optical_joint" type="fixed">
    <origin xyz="0 0 0" rpy="${-M_PI/2} 0 ${-M_PI/2}" />
    <parent link="camera_rgb_frame" />
    <child link="camera_rgb_optical_frame" />
  </joint>
  <link name="camera_rgb_optical_frame"/>

  <joint name="camera_joint" type="fixed">
    <origin xyz="0 ${astra_cam_rel_rgb_py} 0"
            rpy="0 0 0"/>
    <parent link="camera_rgb_frame"/>
    <child link="camera_link"/>
  </joint>
  <link name="camera_link">
    <visual>
      <origin xyz="0 0 0" rpy="${M_PI/2} 0 ${M_PI/2}"/>
      <geometry>
        <mesh filename="package://turtlebot3_description/meshes/sensors/astra.dae" scale="${astra_dae_display_scale} ${astra_dae_display_scale} ${astra_dae_display_scale}"/>
      </geometry>
    </visual>
    <collision>
      <origin xyz="0.0 0.0 0.0" rpy="0 0 0" />
      <geometry>
      <box size="0.0400 0.1650 0.0300"/>
    </geometry>
    </collision>
    <inertial>
      <mass value="0.564" />
      <origin xyz="0 0 0" />
      <inertia ixx="0.003881243" ixy="0.0" ixz="0.0"
               iyy="0.000498940" iyz="0.0"
               izz="0.003879257" />
    </inertial>
  </link>

  <joint name="camera_depth_joint" type="fixed">
    <origin xyz="0 ${astra_depth_rel_rgb_py} 0" rpy="0 0 0" />
    <parent link="camera_rgb_frame" />
    <child link="camera_depth_frame" />
  </joint>
  <link name="camera_depth_frame"/>

  <joint name="camera_depth_optical_joint" type="fixed">
    <origin xyz="0 0 0" rpy="${-M_PI/2} 0 ${-M_PI/2}" />
    <parent link="camera_depth_frame" />
    <child link="camera_depth_optical_frame" />
  </joint>
  <link name="camera_depth_optical_frame"/>

</robot>
